<?xml version="1.0" ?>
<!-- =================================================================================== -->
<!-- |    This document was autogenerated by xacro from src/amphibious_robot_description/description/amphibot.urdf.xacro | -->
<!-- |    EDITING THIS FILE BY HAND IS NOT RECOMMENDED                                 | -->
<!-- =================================================================================== -->
<robot name="amphibot">
  <material name="white">
    <color rgba="1 1 1 1"/>
  </material>
  <material name="red">
    <color rgba="1.0 0.0 0.0 1.0"/>
  </material>
  <material name="blue">
    <color rgba=".2 .2 1 1"/>
  </material>
  <!-- Body -->
  <link name="base_link">
    <visual>
      <geometry>
        <mesh filename="package://amphibious_robot_description/meshes/body.stl" scale="0.001 0.001 0.001"/>
      </geometry>
      <material name="white"/>
    </visual>
    <collision>
      <geometry>
        <mesh filename="package://amphibious_robot_description/meshes/body.stl" scale="0.001 0.001 0.001"/>
      </geometry>
      <material name="white"/>
      <gazebo>
        <material>Gazebo/White</material>
      </gazebo>
    </collision>
    <inertial>
      <mass value="4.8"/>
      <inertia ixx="0.0612" ixy="0.0" ixz="0.0" iyy="0.06948" iyz="0.0" izz="0.0954"/>
    </inertial>
  </link>
  <!--right shaft-->
  <link name="rshaft_link">
    <visual>
      <geometry>
        <mesh filename="package://amphibious_robot_description/meshes/rshaft.stl" scale="0.001 0.001 0.001"/>
      </geometry>
      <material name="blue"/>
    </visual>
    <collision>
      <geometry>
        <mesh filename="package://amphibious_robot_description/meshes/rshaft.stl" scale="0.001 0.001 0.001"/>
      </geometry>
      <material name="blue"/>
      <gazebo>
        <material>Gazebo/Blue</material>
      </gazebo>
    </collision>
    <inertial>
      <mass value="0.1"/>
      <inertia ixx="0.00133" ixy="0.0" ixz="0.0" iyy="0.00133" iyz="0.0" izz="0.0000003125"/>
    </inertial>
  </link>
  <joint name="rshaft_joint" type="fixed">
    <parent link="base_link"/>
    <child link="rshaft_link"/>
    <origin rpy="0 -1.5708 0" xyz=".36 0.005  -.115"/>
  </joint>
  <!--left shaft-->
  <link name="lshaft_link">
    <visual>
      <geometry>
        <mesh filename="package://amphibious_robot_description/meshes/lshaft.stl" scale="0.001 0.001 0.001"/>
      </geometry>
      <material name="blue"/>
    </visual>
    <collision>
      <geometry>
        <mesh filename="package://amphibious_robot_description/meshes/lshaft.stl" scale="0.001 0.001 0.001"/>
      </geometry>
      <material name="blue"/>
      <gazebo>
        <material>Gazebo/Blue</material>
      </gazebo>
    </collision>
    <inertial>
      <mass value="0.1"/>
      <inertia ixx="0.00133" ixy="0.0" ixz="0.0" iyy="0.00133" iyz="0.0" izz="0.0000003125"/>
    </inertial>
  </link>
  <joint name="lshaft_joint" type="fixed">
    <parent link="base_link"/>
    <child link="lshaft_link"/>
    <origin rpy="0 -1.5708 0" xyz=".36 0.355 -.115"/>
  </joint>
  <!-- Left Wheel -->
  <link name="left_wheel_link">
    <visual>
      <geometry>
        <mesh filename="package://amphibious_robot_description/meshes/left_wheel.stl" scale="0.001 0.001 0.001"/>
      </geometry>
      <material name="red"/>
    </visual>
    <collision>
      <geometry>
        <mesh filename="package://amphibious_robot_description/meshes/left_wheel.stl" scale="0.001 0.001 0.001"/>
      </geometry>
      <material name="red"/>
      <gazebo>
        <material>Gazebo/Red</material>
      </gazebo>
    </collision>
    <inertial>
      <mass value="0.5"/>
      <inertia ixx="0.00733" ixy="0.0" ixz="0.0" iyy="0.00733" iyz="0.0" izz="0.00133"/>
    </inertial>
  </link>
  <joint name="left_wheel_joint" type="continuous">
    <parent link="lshaft_link"/>
    <child link="left_wheel_link"/>
    <origin rpy="0 0 0" xyz="0 0 .05"/>
    <axis xyz="0 0 1"/>
  </joint>
  <!-- Right Wheel -->
  <link name="right_wheel_link">
    <visual>
      <geometry>
        <mesh filename="package://amphibious_robot_description/meshes/right_wheel.stl" scale="0.001 0.001 0.001"/>
      </geometry>
      <material name="red"/>
    </visual>
    <collision>
      <geometry>
        <mesh filename="package://amphibious_robot_description/meshes/right_wheel.stl" scale="0.001 0.001 0.001"/>
      </geometry>
      <material name="red"/>
      <gazebo>
        <material>Gazebo/Red</material>
      </gazebo>
    </collision>
    <inertial>
      <mass value="0.5"/>
      <inertia ixx="0.00733" ixy="0.0" ixz="0.0" iyy="0.00733" iyz="0.0" izz="0.00133"/>
    </inertial>
  </link>
  <joint name="right_wheel_joint" type="continuous">
    <parent link="rshaft_link"/>
    <child link="right_wheel_link"/>
    <origin rpy="0 0 0" xyz="0 0 .05"/>
    <axis xyz="0 0 1"/>
  </joint>
</robot>
