<sdf version='1.7'>
  <model name='amphibot'>
    <link name='base_link'>
      <inertial>
        <pose>0.0144 0.0072 -0.0046 0 -0 0</pose>
        <mass>5</mass>
        <inertia>
          <ixx>0.0760856</ixx>
          <ixy>-0.0124416</ixy>
          <ixz>0.0079488</ixz>
          <iyy>0.0995624</iyy>
          <iyz>0.0039744</iyz>
          <izz>0.135289</izz>
        </inertia>
      </inertial>
      <collision name='base_link_collision'>
        <pose>0 0 0 0 -0 0</pose>
        <geometry>
          <mesh>
            <scale>0.001 0.001 0.001</scale>
            <uri>model://amphibious_robot_description/meshes/body.stl</uri>
          </mesh>
        </geometry>
      </collision>
      <collision name='base_link_fixed_joint_lump__lshaft_link_collision_1'>
        <pose>0.36 0.355 -0.115 0 -1.5708 0</pose>
        <geometry>
          <mesh>
            <scale>0.001 0.001 0.001</scale>
            <uri>model://amphibious_robot_description/meshes/lshaft.stl</uri>
          </mesh>
        </geometry>
      </collision>
      <collision name='base_link_fixed_joint_lump__rshaft_link_collision_2'>
        <pose>0.36 0.005 -0.115 0 -1.5708 0</pose>
        <geometry>
          <mesh>
            <scale>0.001 0.001 0.001</scale>
            <uri>model://amphibious_robot_description/meshes/rshaft.stl</uri>
          </mesh>
        </geometry>
      </collision>
      <visual name='base_link_visual'>
        <pose>0 0 0 0 -0 0</pose>
        <geometry>
          <mesh>
            <scale>0.001 0.001 0.001</scale>
            <uri>model://amphibious_robot_description/meshes/body.stl</uri>
          </mesh>
        </geometry>
      </visual>
      <visual name='base_link_fixed_joint_lump__lshaft_link_visual_1'>
        <pose>0.36 0.355 -0.115 0 -1.5708 0</pose>
        <geometry>
          <mesh>
            <scale>0.001 0.001 0.001</scale>
            <uri>model://amphibious_robot_description/meshes/lshaft.stl</uri>
          </mesh>
        </geometry>
      </visual>
      <visual name='base_link_fixed_joint_lump__rshaft_link_visual_2'>
        <pose>0.36 0.005 -0.115 0 -1.5708 0</pose>
        <geometry>
          <mesh>
            <scale>0.001 0.001 0.001</scale>
            <uri>model://amphibious_robot_description/meshes/rshaft.stl</uri>
          </mesh>
        </geometry>
      </visual>
    </link>
    <joint name='left_wheel_joint' type='revolute'>
      <pose relative_to='base_link'>0.31 0.355 -0.115 3.14159 -1.57079 3.14159</pose>
      <parent>base_link</parent>
      <child>left_wheel_link</child>
      <axis>
        <xyz>0 1 0</xyz>
        <limit>
          <lower>-1e+16</lower>
          <upper>1e+16</upper>
        </limit>
        <dynamics>
          <spring_reference>0</spring_reference>
          <spring_stiffness>0</spring_stiffness>
        </dynamics>
      </axis>
    </joint>
    <link name='left_wheel_link'>
      <pose relative_to='left_wheel_joint'>0 0 0 0 -0 0</pose>
      <inertial>
        <pose>0 0 0 0 -0 0</pose>
        <mass>0.5</mass>
        <inertia>
          <ixx>0.00733</ixx>
          <ixy>0</ixy>
          <ixz>0</ixz>
          <iyy>0.00733</iyy>
          <iyz>0</iyz>
          <izz>0.00133</izz>
        </inertia>
      </inertial>
      <collision name='left_wheel_link_collision'>
        <pose>0 0 0 0 -0 0</pose>
        <geometry>
          <mesh>
            <scale>0.001 0.001 0.001</scale>
            <uri>model://amphibious_robot_description/meshes/left_wheel.stl</uri>
          </mesh>
        </geometry>
      </collision>
      <visual name='left_wheel_link_visual'>
        <pose>0 0 0 0 -0 0</pose>
        <geometry>
          <mesh>
            <scale>0.001 0.001 0.001</scale>
            <uri>model://amphibious_robot_description/meshes/left_wheel.stl</uri>
          </mesh>
        </geometry>
      </visual>
    </link>
    <joint name='right_wheel_joint' type='revolute'>
      <pose relative_to='base_link'>0.31 0.005 -0.115 3.14159 -1.57079 3.14159</pose>
      <parent>base_link</parent>
      <child>right_wheel_link</child>
      <axis>
        <xyz>0 1 0</xyz>
        <limit>
          <lower>-1e+16</lower>
          <upper>1e+16</upper>
        </limit>
        <dynamics>
          <spring_reference>0</spring_reference>
          <spring_stiffness>0</spring_stiffness>
        </dynamics>
      </axis>
    </joint>
    <link name='right_wheel_link'>
      <pose relative_to='right_wheel_joint'>0 0 0 0 -0 0</pose>
      <inertial>
        <pose>0 0 0 0 -0 0</pose>
        <mass>0.5</mass>
        <inertia>
          <ixx>0.00733</ixx>
          <ixy>0</ixy>
          <ixz>0</ixz>
          <iyy>0.00733</iyy>
          <iyz>0</iyz>
          <izz>0.00133</izz>
        </inertia>
      </inertial>
      <collision name='right_wheel_link_collision'>
        <pose>0 0 0 0 -0 0</pose>
        <geometry>
          <mesh>
            <scale>0.001 0.001 0.001</scale>
            <uri>model://amphibious_robot_description/meshes/right_wheel.stl</uri>
          </mesh>
        </geometry>
      </collision>
      <visual name='right_wheel_link_visual'>
        <pose>0 0 0 0 -0 0</pose>
        <geometry>
          <mesh>
            <scale>0.001 0.001 0.001</scale>
            <uri>model://amphibious_robot_description/meshes/right_wheel.stl</uri>
          </mesh>
        </geometry>
      </visual>
    </link>
  </model>
</sdf>
